{
           "registryname": "automatic_assembly_machine",
    "localizedname": "Автоматическая Сборочная Машина",
    "color": "354d73",
    "parts": [
        {
            "x": -1,
            "y": 0,
            "z": 0,
            "elements": [
                "galaxyspace:machineframes@1"
            ]
        },
        {
            "x": -2,
            "y": 0,
            "z": 0,
            "elements": [
                "galaxyspace:machineframes@1"
            ]
        },
        {
            "x": 1,
            "y": 0,
            "z": 0,
            "elements": [
                "galaxyspace:machineframes@1"
            ]
        },
        {
            "x": 2,
            "y": 0,
            "z": 0,
            "elements": [
                "galaxyspace:machineframes@1"
            ]
        },
        {
            "x": -3,
            "y": 0,
            "z": 8,
            "elements": [
                "galaxyspace:machineframes@1"
            ]
        },
        {
            "x": -3,
            "y": -2,
            "z": 7,
            "elements": [
                "galaxyspace:futureglass@6"
            ]
        },
        {
            "x": -3,
            "y": -4,
            "z": 6,
            "elements": [
                "galaxyspace:machineframes@1"
            ]
        },
        {
            "x": -2,
            "y": -4,
            "z": 6,
            "elements": [
                "galaxyspace:machineframes@1"
            ]
        },
        {
            "x": 0,
            "y": 0,
            "z": 8,
           
            "elements": [
                "modularmachinery:blockcasing@3"
            ]
        },
        {
            "x": -1,
            "y": -4,
            "z": 6,
            "elements": [
                "galaxyspace:machineframes@1"
            ]
        },
        {
            "x": 0,
            "y": -4,
            "z": 6,
            "elements": [
                "galaxyspace:machineframes@1"
            ]
        },
        {
            "x": 3,
            "y": 0,
            "z": 8,
            "elements": [
                "galaxyspace:machineframes@1"
            ]
        },
        {
            "x": 1,
            "y": -4,
            "z": 6,
            "elements": [
                "galaxyspace:machineframes@1"
            ]
        },
        {
            "x": 3,
            "y": -2,
            "z": 7,
            "elements": [
                "galaxyspace:futureglass@6"
            ]
        },
        {
            "x": 2,
            "y": -4,
            "z": 6,
            "elements": [
                "galaxyspace:machineframes@1"
            ]
        },
        {
            "x": 3,
            "y": -4,
            "z": 6,
            "elements": [
                "galaxyspace:machineframes@1"
            ]
        },
        {
            "x": 2,
            "y": -1,
            "z": 0,
            "elements": [
                "railcraft:post_metal@7"
            ]
        },
        {
            "x": -2,
            "y": -1,
            "z": 0,
            "elements": [
                "railcraft:post_metal@7"
            ]
        },
        {
            "x": -3,
            "y": -1,
            "z": 7,
            "elements": [
                "galaxyspace:futureglass@6"
            ]
        },
        {
            "x": -2,
            "y": 1,
            "z": 8,
           
            "elements": [
                "generalized_input_item"
            ]
        },
        {
            "x": -3,
            "y": -3,
            "z": 6,
            "elements": [
                "galaxyspace:futureglass@6"
            ]
        },
        {
            "x": -1,
            "y": 1,
            "z": 8,
            "elements": [
                "galaxyspace:machineframes@1"
            ]
        },
        {
            "x": 0,
            "y": 1,
            "z": 8,
            "elements": [
                "galaxyspace:machineframes@1"
            ]
        },
        {
            "x": 1,
            "y": 1,
            "z": 8,
            "elements": [
                "galaxyspace:machineframes@1"
            ]
        },
        {
            "x": 2,
            "y": 1,
            "z": 8,
           
            "elements": [
                "generalized_input_item"
            ]
        },
        {
            "x": 3,
            "y": -1,
            "z": 7,
            "elements": [
                "galaxyspace:futureglass@6"
            ]
        },
        {
            "x": 3,
            "y": -3,
            "z": 6,
            "elements": [
                "galaxyspace:futureglass@6"
            ]
        },
        {
            "x": 2,
            "y": -2,
            "z": 0,
            "elements": [
                "railcraft:post_metal@7"
            ]
        },
        {
            "x": -2,
            "y": -2,
            "z": 0,
            "elements": [
                "railcraft:post_metal@7"
            ]
        },
        {
            "x": -3,
            "y": 0,
            "z": 7,
            "elements": [
                "galaxyspace:machineframes@1"
            ]
        },
        {
            "x": -3,
            "y": -2,
            "z": 6,
            "elements": [
                "galaxyspace:futureglass@6"
            ]
        },
        {
            "x": -3,
            "y": -4,
            "z": 5,
            "elements": [
                "galaxyspace:machineframes@1"
            ]
        },
        {
            "x": -2,
            "y": -4,
            "z": 5,
            "elements": [
                "galaxyspace:machineframes@1"
            ]
        },
        {
            "x": 0,
            "y": 0,
            "z": 7,
           
            "elements": [
                "modularmachinery:blockcasing@3"
            ]
        },
        {
            "x": -1,
            "y": -4,
            "z": 5,
            "elements": [
                "galaxyspace:machineframes@1"
            ]
        },
        {
            "x": 0,
            "y": -4,
            "z": 5,
            "elements": [
                "galaxyspace:machineframes@1"
            ]
        },
        {
            "x": 3,
            "y": 0,
            "z": 7,
            "elements": [
                "galaxyspace:machineframes@1"
            ]
        },
        {
            "x": 1,
            "y": -4,
            "z": 5,
            "elements": [
                "galaxyspace:machineframes@1"
            ]
        },
        {
            "x": 3,
            "y": -2,
            "z": 6,
            "elements": [
                "galaxyspace:futureglass@6"
            ]
        },
        {
            "x": 2,
            "y": -4,
            "z": 5,
            "elements": [
                "galaxyspace:machineframes@1"
            ]
        },
        {
            "x": 3,
            "y": -4,
            "z": 5,
            "elements": [
                "galaxyspace:machineframes@1"
            ]
        },
        {
            "x": 2,
            "y": -3,
            "z": 0,
            "elements": [
                "railcraft:post_metal@7"
            ]
        },
        {
            "x": -2,
            "y": -3,
            "z": 0,
            "elements": [
                "railcraft:post_metal@7"
            ]
        },
        {
            "x": -3,
            "y": -1,
            "z": 6,
            "elements": [
                "galaxyspace:futureglass@6"
            ]
        },
        {
            "x": -2,
            "y": 1,
            "z": 7,
           
            "elements": [
                "modularmachinery:blockcasing@1"
            ]
        },
        {
            "x": -3,
            "y": -3,
            "z": 5,
            "elements": [
                "galaxyspace:machineframes@1"
            ]
        },
        {
            "x": -1,
            "y": 1,
            "z": 7,
            "elements": [
                "galaxyspace:machineframes@1"
            ]
        },
        {
            "x": 0,
            "y": 1,
            "z": 7,
            "elements": [
                "galaxyspace:machineframes@1"
            ]
        },
        {
            "x": 1,
            "y": 1,
            "z": 7,
            "elements": [
                "galaxyspace:machineframes@1"
            ]
        },
        {
            "x": 2,
            "y": 1,
            "z": 7,
           
            "elements": [
                "modularmachinery:blockcasing@1"
            ]
        },
        {
            "x": 3,
            "y": -1,
            "z": 6,
            "elements": [
                "galaxyspace:futureglass@6"
            ]
        },
        {
            "x": 3,
            "y": -3,
            "z": 5,
            "elements": [
                "galaxyspace:machineframes@1"
            ]
        },
        {
            "x": 2,
            "y": -4,
            "z": 0,
            "elements": [
                "galaxyspace:machineframes@1"
            ]
        },
        {
            "x": 1,
            "y": -4,
            "z": 0,
            "elements": [
                "galaxyspace:machineframes@1"
            ]
        },
        {
            "x": 0,
            "y": -4,
            "z": 0,
            "elements": [
                "galaxyspace:machineframes@1"
            ]
        },
        {
            "x": -1,
            "y": -4,
            "z": 0,
            "elements": [
                "galaxyspace:machineframes@1"
            ]
        },
        {
            "x": -2,
            "y": -4,
            "z": 0,
            "elements": [
                "galaxyspace:machineframes@1"
            ]
        },
        {
            "x": -3,
            "y": 0,
            "z": 6,
            "elements": [
                "galaxyspace:machineframes@1"
            ]
        },
        {
            "x": -3,
            "y": -2,
            "z": 5,
            "elements": [
                "galaxyspace:machineframes@1"
            ]
        },
        {
            "x": -3,
            "y": -4,
            "z": 4,
            "elements": [
                "galaxyspace:machineframes@1"
            ]
        },
        {
            "x": -2,
            "y": -4,
            "z": 4,
            "elements": [
                "galaxyspace:machineframes@1"
            ]
        },
        {
            "x": 0,
            "y": 0,
            "z": 6,
           
            "elements": [
                "modularmachinery:blockcasing@3"
            ]
        },
        {
            "x": -1,
            "y": -4,
            "z": 4,
            "elements": [
                "galaxyspace:machineframes@1"
            ]
        },
        {
            "x": 0,
            "y": -4,
            "z": 4,
            "elements": [
                "galaxyspace:machineframes@1"
            ]
        },
        {
            "x": 3,
            "y": 0,
            "z": 6,
            "elements": [
                "galaxyspace:machineframes@1"
            ]
        },
        {
            "x": 1,
            "y": -4,
            "z": 4,
            "elements": [
                "galaxyspace:machineframes@1"
            ]
        },
        {
            "x": 3,
            "y": -2,
            "z": 5,
            "elements": [
                "galaxyspace:machineframes@1"
            ]
        },
        {
            "x": 2,
            "y": -4,
            "z": 4,
            "elements": [
                "galaxyspace:machineframes@1"
            ]
        },
        {
            "x": 3,
            "y": -4,
            "z": 4,
            "elements": [
                "galaxyspace:machineframes@1"
            ]
        },
        {
            "x": -3,
            "y": -1,
            "z": 5,
            "elements": [
                "galaxyspace:machineframes@1"
            ]
        },
        {
            "x": -2,
            "y": 1,
            "z": 6,
           
            "elements": [
                "generalized_input_item"
            ]
        },
        {
            "x": -3,
            "y": -3,
            "z": 4,
            "elements": [
                "galaxyspace:futureglass@6"
            ]
        },
        {
            "x": -1,
            "y": 1,
            "z": 6,
            "elements": [
                "galaxyspace:machineframes@1"
            ]
        },
        {
            "x": 0,
            "y": 1,
            "z": 6,
            "elements": [
                "galaxyspace:machineframes@1"
            ]
        },
        {
            "x": 1,
            "y": 1,
            "z": 6,
            "elements": [
                "galaxyspace:machineframes@1"
            ]
        },
        {
            "x": 2,
            "y": 1,
            "z": 6,
           
            "elements": [
                "generalized_input_item"
            ]
        },
        {
            "x": 3,
            "y": -1,
            "z": 5,
            "elements": [
                "galaxyspace:machineframes@1"
            ]
        },
        {
            "x": 3,
            "y": -3,
            "z": 4,
            "elements": [
                "galaxyspace:futureglass@6"
            ]
        },
        {
            "x": -3,
            "y": 0,
            "z": 5,
            "elements": [
                "galaxyspace:machineframes@1"
            ]
        },
        {
            "x": -3,
            "y": -2,
            "z": 4,
            "elements": [
                "galaxyspace:futureglass@6"
            ]
        },
        {
            "x": -3,
            "y": -4,
            "z": 3,
            "elements": [
                "galaxyspace:machineframes@1"
            ]
        },
        {
            "x": -2,
            "y": -4,
            "z": 3,
            "elements": [
                "galaxyspace:machineframes@1"
            ]
        },
        {
            "x": 0,
            "y": 0,
            "z": 5,
           
            "elements": [
                "modularmachinery:blockcasing@3"
            ]
        },
        {
            "x": -1,
            "y": -4,
            "z": 3,
            "elements": [
                "galaxyspace:machineframes@1"
            ]
        },
        {
            "x": 0,
            "y": -4,
            "z": 3,
            "elements": [
                "galaxyspace:machineframes@1"
            ]
        },
        {
            "x": 3,
            "y": 0,
            "z": 5,
            "elements": [
                "galaxyspace:machineframes@1"
            ]
        },
        {
            "x": 1,
            "y": -4,
            "z": 3,
            "elements": [
                "galaxyspace:machineframes@1"
            ]
        },
        {
            "x": 3,
            "y": -2,
            "z": 4,
            "elements": [
                "galaxyspace:futureglass@6"
            ]
        },
        {
            "x": 2,
            "y": -4,
            "z": 3,
            "elements": [
                "galaxyspace:machineframes@1"
            ]
        },
        {
            "x": 3,
            "y": -4,
            "z": 3,
            "elements": [
                "galaxyspace:machineframes@1"
            ]
        },
        {
            "x": -3,
            "y": -1,
            "z": 4,
            "elements": [
                "galaxyspace:futureglass@6"
            ]
        },
        {
            "x": -2,
            "y": 1,
            "z": 5,
           
            "elements": [
                "modularmachinery:blockcasing@1"
            ]
        },
        {
            "x": -3,
            "y": -3,
            "z": 3,
            "elements": [
                "galaxyspace:futureglass@6"
            ]
        },
        {
            "x": -1,
            "y": 1,
            "z": 5,
            "elements": [
                "galaxyspace:machineframes@1"
            ]
        },
                {
            "x": 0,
            "y": 1,
            "z": 5,
          
            "elements": [
               "blockparallelcontroller_g"
            ]
        },
        {
            "x": 1,
            "y": 1,
            "z": 5,
            "elements": [
                "galaxyspace:machineframes@1"
            ]
        },
        {
            "x": 2,
            "y": 1,
            "z": 5,
           
            "elements": [
                "modularmachinery:blockcasing@1"
            ]
        },
        {
            "x": 3,
            "y": -1,
            "z": 4,
            "elements": [
                "galaxyspace:futureglass@6"
            ]
        },
        {
            "x": 3,
            "y": -3,
            "z": 3,
            "elements": [
                "galaxyspace:futureglass@6"
            ]
        },
        {
            "x": -3,
            "y": 0,
            "z": 4,
            "elements": [
                "galaxyspace:machineframes@1"
            ]
        },
        {
            "x": -3,
            "y": -2,
            "z": 3,
            "elements": [
                "galaxyspace:futureglass@6"
            ]
        },
        {
            "x": -3,
            "y": -4,
            "z": 2,
            "elements": [
                "galaxyspace:machineframes@1"
            ]
        },
        {
            "x": 0,
            "y": 0,
            "z": 4,
           
            "elements": [
                "modularmachinery:blockcasing@3"
            ]
        },
        {
            "x": -2,
            "y": -4,
            "z": 2,
            "elements": [
                "galaxyspace:machineframes@1"
            ]
        },
        {
            "x": -1,
            "y": -4,
            "z": 2,
            "elements": [
                "galaxyspace:machineframes@1"
            ]
        },
        {
            "x": 0,
            "y": -4,
            "z": 2,
            "elements": [
                "galaxyspace:machineframes@1"
            ]
        },
        {
            "x": 3,
            "y": 0,
            "z": 4,
            "elements": [
                "galaxyspace:machineframes@1"
            ]
        },
        {
            "x": 1,
            "y": -4,
            "z": 2,
            "elements": [
                "galaxyspace:machineframes@1"
            ]
        },
        {
            "x": 3,
            "y": -2,
            "z": 3,
            "elements": [
                "galaxyspace:futureglass@6"
            ]
        },
        {
            "x": 2,
            "y": -4,
            "z": 2,
            "elements": [
                "galaxyspace:machineframes@1"
            ]
        },
        {
            "x": 3,
            "y": -4,
            "z": 2,
            "elements": [
                "galaxyspace:machineframes@1"
            ]
        },
        {
            "x": -2,
            "y": -4,
            "z": 10,
            "elements": [
                "galaxyspace:machineframes@1"
            ]
        },
        {
            "x": -1,
            "y": -4,
            "z": 10,
            "elements": [
                "galaxyspace:machineframes@1"
            ]
        },
        {
            "x": 0,
            "y": -4,
            "z": 10,
           
            "elements": [
                "generalized_output_item"
            ]
        },
        {
            "x": 1,
            "y": -4,
            "z": 10,
            "elements": [
                "galaxyspace:machineframes@1"
            ]
        },
        {
            "x": 2,
            "y": -4,
            "z": 10,
            "elements": [
                "galaxyspace:machineframes@1"
            ]
        },
        {
            "x": -3,
            "y": -1,
            "z": 3,
            "elements": [
                "galaxyspace:futureglass@6"
            ]
        },
        {
            "x": -2,
            "y": 1,
            "z": 4,
           
            "elements": [
                "generalized_input_item"
            ]
        },
        {
            "x": -3,
            "y": -3,
            "z": 2,
            "elements": [
                "galaxyspace:futureglass@6"
            ]
        },
        {
            "x": -1,
            "y": 1,
            "z": 4,
            "elements": [
                "galaxyspace:machineframes@1"
            ]
        },
        {
            "x": 0,
            "y": 1,
            "z": 4,
            "elements": [
                "galaxyspace:machineframes@1"
            ]
        },
        {
            "x": 1,
            "y": 1,
            "z": 4,
            "elements": [
                "galaxyspace:machineframes@1"
            ]
        },
        {
            "x": 2,
            "y": 1,
            "z": 4,
           
            "elements": [
                "generalized_input_item"
            ]
        },
        {
            "x": 3,
            "y": -1,
            "z": 3,
            "elements": [
                "galaxyspace:futureglass@6"
            ]
        },
        {
            "x": 3,
            "y": -3,
            "z": 2,
            "elements": [
                "galaxyspace:futureglass@6"
            ]
        },
        {
            "x": -2,
            "y": -3,
            "z": 10,
            "elements": [
                "railcraft:post_metal@7"
            ]
        },
        {
            "x": 2,
            "y": -3,
            "z": 10,
            "elements": [
                "railcraft:post_metal@7"
            ]
        },
        {
            "x": -3,
            "y": 0,
            "z": 3,
            "elements": [
                "galaxyspace:machineframes@1"
            ]
        },
        {
            "x": -3,
            "y": -2,
            "z": 2,
            "elements": [
                "galaxyspace:futureglass@6"
            ]
        },
        {
            "x": -3,
            "y": -4,
            "z": 1,
            "elements": [
                "galaxyspace:machineframes@1"
            ]
        },
        {
            "x": 0,
            "y": 0,
            "z": 3,
           
            "elements": [
                "modularmachinery:blockcasing@3"
            ]
        },
        {
            "x": -2,
            "y": -4,
            "z": 1,
            "elements": [
                "galaxyspace:machineframes@1"
            ]
        },
        {
            "x": -1,
            "y": -4,
            "z": 1,
            "elements": [
                "galaxyspace:machineframes@1"
            ]
        },
        {
            "x": 0,
            "y": -4,
            "z": 1,
            "elements": [
                "galaxyspace:machineframes@1"
            ]
        },
        {
            "x": 3,
            "y": 0,
            "z": 3,
            "elements": [
                "galaxyspace:machineframes@1"
            ]
        },
        {
            "x": 1,
            "y": -4,
            "z": 1,
            "elements": [
                "galaxyspace:machineframes@1"
            ]
        },
        {
            "x": 3,
            "y": -2,
            "z": 2,
            "elements": [
                "galaxyspace:futureglass@6"
            ]
        },
        {
            "x": 2,
            "y": -4,
            "z": 1,
            "elements": [
                "galaxyspace:machineframes@1"
            ]
        },
        {
            "x": 3,
            "y": -4,
            "z": 1,
            "elements": [
                "galaxyspace:machineframes@1"
            ]
        },
        {
            "x": -3,
            "y": -4,
            "z": 9,
            "elements": [
                "galaxyspace:machineframes@1"
            ]
        },
        {
            "x": -2,
            "y": -2,
            "z": 10,
            "elements": [
                "railcraft:post_metal@7"
            ]
        },
        {
            "x": -2,
            "y": -4,
            "z": 9,
            "elements": [
                "galaxyspace:machineframes@1"
            ]
        },
        {
            "x": -1,
            "y": -4,
            "z": 9,
            "elements": [
                "galaxyspace:machineframes@1"
            ]
        },
        {
            "x": 0,
            "y": -4,
            "z": 9,
            "elements": [
                "galaxyspace:machineframes@1"
            ]
        },
        {
            "x": 2,
            "y": -2,
            "z": 10,
            "elements": [
                "railcraft:post_metal@7"
            ]
        },
        {
            "x": 1,
            "y": -4,
            "z": 9,
            "elements": [
                "galaxyspace:machineframes@1"
            ]
        },
        {
            "x": 2,
            "y": -4,
            "z": 9,
            "elements": [
                "galaxyspace:machineframes@1"
            ]
        },
        {
            "x": 3,
            "y": -4,
            "z": 9,
            "elements": [
                "galaxyspace:machineframes@1"
            ]
        },
        {
            "x": -3,
            "y": -1,
            "z": 2,
            "elements": [
                "galaxyspace:futureglass@6"
            ]
        },
        {
            "x": -2,
            "y": 1,
            "z": 3,
           
            "elements": [
                "modularmachinery:blockcasing@1"
            ]
        },
        {
            "x": -3,
            "y": -3,
            "z": 1,
            "elements": [
                "galaxyspace:machineframes@1"
            ]
        },
        {
            "x": -1,
            "y": 1,
            "z": 3,
            "elements": [
                "galaxyspace:machineframes@1"
            ]
        },
        {
            "x": 0,
            "y": 1,
            "z": 3,
            "elements": [
                "galaxyspace:machineframes@1"
            ]
        },
        {
            "x": 1,
            "y": 1,
            "z": 3,
            "elements": [
                "galaxyspace:machineframes@1"
            ]
        },
        {
            "x": 2,
            "y": 1,
            "z": 3,
           
            "elements": [
                "modularmachinery:blockcasing@1"
            ]
        },
        {
            "x": 3,
            "y": -1,
            "z": 2,
            "elements": [
                "galaxyspace:futureglass@6"
            ]
        },
        {
            "x": 3,
            "y": -3,
            "z": 1,
            "elements": [
                "galaxyspace:machineframes@1"
            ]
        },
        {
            "x": -3,
            "y": -3,
            "z": 9,
            "elements": [
                "galaxyspace:machineframes@1"
            ]
        },
        {
            "x": -2,
            "y": -1,
            "z": 10,
            "elements": [
                "railcraft:post_metal@7"
            ]
        },
        {
            "x": 2,
            "y": -1,
            "z": 10,
            "elements": [
                "railcraft:post_metal@7"
            ]
        },
        {
            "x": 3,
            "y": -3,
            "z": 9,
            "elements": [
                "galaxyspace:machineframes@1"
            ]
        },
        {
            "x": -3,
            "y": 0,
            "z": 2,
            "elements": [
                "galaxyspace:machineframes@1"
            ]
        },
        {
            "x": -3,
            "y": -2,
            "z": 1,
            "elements": [
                "galaxyspace:machineframes@1"
            ]
        },
        {
            "x": 0,
            "y": 0,
            "z": 2,
           
            "elements": [
                "modularmachinery:blockcasing@3"
            ]
        },
        {
            "x": 3,
            "y": 0,
            "z": 2,
            "elements": [
                "galaxyspace:machineframes@1"
            ]
        },
        {
            "x": 3,
            "y": -2,
            "z": 1,
            "elements": [
                "galaxyspace:machineframes@1"
            ]
        },
        {
            "x": -3,
            "y": -2,
            "z": 9,
            "elements": [
                "galaxyspace:machineframes@1"
            ]
        },
        {
            "x": -2,
            "y": 0,
            "z": 10,
            "elements": [
                "galaxyspace:machineframes@1"
            ]
        },
        {
            "x": -3,
            "y": -4,
            "z": 8,
            "elements": [
                "galaxyspace:machineframes@1"
            ]
        },
        {
            "x": -1,
            "y": 0,
            "z": 10,
            "elements": [
                "galaxyspace:machineframes@1"
            ]
        },
        {
            "x": -2,
            "y": -4,
            "z": 8,
            "elements": [
                "galaxyspace:machineframes@1"
            ]
        },
        {
            "x": 0,
            "y": 0,
            "z": 10,
            
            "elements": [
                  "modularmachinery:blockenergyinputhatch"
            ]
        },
        {
            "x": -1,
            "y": -4,
            "z": 8,
            "elements": [
                "galaxyspace:machineframes@1"
            ]
        },
        {
            "x": 1,
            "y": 0,
            "z": 10,
            "elements": [
                "galaxyspace:machineframes@1"
            ]
        },
        {
            "x": 0,
            "y": -4,
            "z": 8,
            "elements": [
                "galaxyspace:machineframes@1"
            ]
        },
        {
            "x": 2,
            "y": 0,
            "z": 10,
            "elements": [
                "galaxyspace:machineframes@1"
            ]
        },
        {
            "x": 1,
            "y": -4,
            "z": 8,
            "elements": [
                "galaxyspace:machineframes@1"
            ]
        },
        {
            "x": 3,
            "y": -2,
            "z": 9,
            "elements": [
                "galaxyspace:machineframes@1"
            ]
        },
        {
            "x": 2,
            "y": -4,
            "z": 8,
            "elements": [
                "galaxyspace:machineframes@1"
            ]
        },
        {
            "x": 3,
            "y": -4,
            "z": 8,
            "elements": [
                "galaxyspace:machineframes@1"
            ]
        },
        {
            "x": -3,
            "y": -1,
            "z": 1,
            "elements": [
                "galaxyspace:machineframes@1"
            ]
        },
        {
            "x": -2,
            "y": 1,
            "z": 2,
           
            "elements": [
                "generalized_input_item"
            ]
        },
        {
            "x": -1,
            "y": 1,
            "z": 2,
            "elements": [
                "galaxyspace:machineframes@1"
            ]
        },
        {
            "x": 0,
            "y": 1,
            "z": 2,
            "elements": [
                "galaxyspace:machineframes@1"
            ]
        },
        {
            "x": 1,
            "y": 1,
            "z": 2,
            "elements": [
                "galaxyspace:machineframes@1"
            ]
        },
        {
            "x": 2,
            "y": 1,
            "z": 2,
           
            "elements": [
                "generalized_input_item"
            ]
        },
        {
            "x": 3,
            "y": -1,
            "z": 1,
            "elements": [
                "galaxyspace:machineframes@1"
            ]
        },
        {
            "x": -3,
            "y": -1,
            "z": 9,
            "elements": [
                "galaxyspace:machineframes@1"
            ]
        },
        {
            "x": -3,
            "y": -3,
            "z": 8,
            "elements": [
                "galaxyspace:futureglass@6"
            ]
        },
        {
            "x": 3,
            "y": -1,
            "z": 9,
            "elements": [
                "galaxyspace:machineframes@1"
            ]
        },
        {
            "x": 3,
            "y": -3,
            "z": 8,
            "elements": [
                "galaxyspace:futureglass@6"
            ]
        },
        {
            "x": -3,
            "y": 0,
            "z": 1,
            "elements": [
                "galaxyspace:machineframes@1"
            ]
        },
        {
            "x": 0,
            "y": 0,
            "z": 1,
           
            "elements": [
                "modularmachinery:blockcasing@3"
            ]
        },
        {
            "x": 3,
            "y": 0,
            "z": 1,
            "elements": [
                "galaxyspace:machineframes@1"
            ]
        },
        {
            "x": -3,
            "y": 0,
            "z": 9,
            "elements": [
                "galaxyspace:machineframes@1"
            ]
        },
        {
            "x": -3,
            "y": -2,
            "z": 8,
            "elements": [
                "galaxyspace:futureglass@6"
            ]
        },
        {
            "x": -3,
            "y": -4,
            "z": 7,
            "elements": [
                "galaxyspace:machineframes@1"
            ]
        },
        {
            "x": -2,
            "y": -4,
            "z": 7,
            "elements": [
                "galaxyspace:machineframes@1"
            ]
        },
        {
            "x": 0,
            "y": 0,
            "z": 9,
           
            "elements": [
                "modularmachinery:blockcasing@3"
            ]
        },
        {
            "x": -1,
            "y": -4,
            "z": 7,
            "elements": [
                "galaxyspace:machineframes@1"
            ]
        },
        {
            "x": 0,
            "y": -4,
            "z": 7,
            "elements": [
                "galaxyspace:machineframes@1"
            ]
        },
        {
            "x": 3,
            "y": 0,
            "z": 9,
            "elements": [
                "galaxyspace:machineframes@1"
            ]
        },
        {
            "x": 1,
            "y": -4,
            "z": 7,
            "elements": [
                "galaxyspace:machineframes@1"
            ]
        },
        {
            "x": 3,
            "y": -2,
            "z": 8,
            "elements": [
                "galaxyspace:futureglass@6"
            ]
        },
        {
            "x": 2,
            "y": -4,
            "z": 7,
            "elements": [
                "galaxyspace:machineframes@1"
            ]
        },
        {
            "x": 3,
            "y": -4,
            "z": 7,
            "elements": [
                "galaxyspace:machineframes@1"
            ]
        },
        {
            "x": -2,
            "y": 1,
            "z": 1,
           
            "elements": [
                "modularmachinery:blockcasing@1"
            ]
        },
        {
            "x": -1,
            "y": 1,
            "z": 1,
            "elements": [
                "galaxyspace:machineframes@1"
            ]
        },
        {
            "x": 0,
            "y": 1,
            "z": 1,
            "elements": [
                "galaxyspace:machineframes@1"
            ]
        },
        {
            "x": 1,
            "y": 1,
            "z": 1,
            "elements": [
                "galaxyspace:machineframes@1"
            ]
        },
        {
            "x": 2,
            "y": 1,
            "z": 1,
           
            "elements": [
                "modularmachinery:blockcasing@1"
            ]
        },
        {
            "x": -3,
            "y": -1,
            "z": 8,
            "elements": [
                "galaxyspace:futureglass@6"
            ]
        },
        {
            "x": -2,
            "y": 1,
            "z": 9,
           
            "elements": [
                "modularmachinery:blockcasing@1"
            ]
        },
        {
            "x": -3,
            "y": -3,
            "z": 7,
            "elements": [
                "galaxyspace:futureglass@6"
            ]
        },
        {
            "x": -1,
            "y": 1,
            "z": 9,
            "elements": [
                "galaxyspace:machineframes@1"
            ]
        },
        {
            "x": 0,
            "y": 1,
            "z": 9,
            "elements": [
                "galaxyspace:machineframes@1"
            ]
        },
        {
            "x": 1,
            "y": 1,
            "z": 9,
            "elements": [
                "galaxyspace:machineframes@1"
            ]
        },
        {
            "x": 2,
            "y": 1,
            "z": 9,
           
            "elements": [
                "modularmachinery:blockcasing@1"
            ]
        },
        {
            "x": 3,
            "y": -1,
            "z": 8,
            "elements": [
                "galaxyspace:futureglass@6"
            ]
        },
        {
            "x": 3,
            "y": -3,
            "z": 7,
            "elements": [
                "galaxyspace:futureglass@6"
            ]
        }
    ]}

