{
      "registryname": "fast_coke_oven",
    "localizedname": "Быстрая Коксовая Печь",
    "color": "B69714",
    "parts": [
        {
            "x": -1,
            "y": 0,
            "z": 0,
            "elements": [
                "railcraft:coke_oven@0"
            ]
        },
        {
            "x": -1,
            "y": 0,
            "z": 1,
            
            "elements": [
                "generalized_output_item"
            ]
        },
        {
            "x": 0,
            "y": 2,
            "z": 2,
            "elements": [
                "railcraft:coke_oven@0"
            ]
        },
        {
            "x": 1,
            "y": 2,
            "z": 1,
            "elements": [
                "railcraft:coke_oven@0"
            ]
        },
        {
            "x": 0,
            "y": 0,
            "z": 1,
            "elements": [
                "generalized_output_fluid"
            ]
        },
        {
            "x": 1,
            "y": 0,
            "z": 0,
            "elements": [
                "railcraft:coke_oven@0"
            ]
        },
        {
            "x": -1,
            "y": 0,
            "z": 2,
            "elements": [
                "railcraft:coke_oven@0"
            ]
        },
        {
            "x": 1,
            "y": 2,
            "z": 2,
            "elements": [
                "railcraft:coke_oven@0"
            ]
        },
        {
            "x": 1,
            "y": 0,
            "z": 1,
          
            "elements": [
                "generalized_input_item"
            ]
        },
        {
            "x": 0,
            "y": 0,
            "z": 2,
     
            "elements": [
                "modularmachinery:blockenergyinputhatch"
            ]
        },
        {
            "x": 1,
            "y": 0,
            "z": 2,
            "elements": [
                "railcraft:coke_oven@0"
            ]
        },
        {
            "x": -1,
            "y": 3,
            "z": 0,
            "elements": [
                "railcraft:coke_oven@0"
            ]
        },
        {
            "x": 0,
            "y": 3,
            "z": 0,
            "elements": [
                "railcraft:coke_oven@0"
            ]
        },
        {
            "x": -1,
            "y": 3,
            "z": 1,
            "elements": [
                "railcraft:coke_oven@0"
            ]
        },
        {
            "x": 0,
            "y": 3,
            "z": 1,
            "elements": [
                "railcraft:coke_oven@0"
            ]
        },
        {
            "x": 1,
            "y": 3,
            "z": 0,
            "elements": [
                "railcraft:coke_oven@0"
            ]
        },
        {
            "x": -1,
            "y": 1,
            "z": 0,
            "elements": [
                "railcraft:coke_oven@0"
            ]
        },
        {
            "x": -1,
            "y": 3,
            "z": 2,
            "elements": [
                "railcraft:coke_oven@0"
            ]
        },
        {
            "x": 0,
            "y": 3,
            "z": 2,
            "elements": [
                "railcraft:coke_oven@0"
            ]
        },
        {
            "x": 1,
            "y": 3,
            "z": 1,
            "elements": [
                "railcraft:coke_oven@0"
            ]
        },
        {
            "x": 0,
            "y": 1,
            "z": 0,
            "elements": [
                "railcraft:coke_oven@0"
            ]
        },
        {
            "x": -1,
            "y": 1,
            "z": 1,
            "elements": [
                "railcraft:coke_oven@0"
            ]
        },
        {
            "x": 1,
            "y": 3,
            "z": 2,
            "elements": [
                "railcraft:coke_oven@0"
            ]
        },
        {
            "x": 0,
            "y": 1,
            "z": 1,
            "elements": [
                "railcraft:creosote@0"
            ]
        },
        {
            "x": 1,
            "y": 1,
            "z": 0,
            "elements": [
                "railcraft:coke_oven@0"
            ]
        },
        {
            "x": -1,
            "y": 1,
            "z": 2,
            "elements": [
                "railcraft:coke_oven@0"
            ]
        },
        {
            "x": 0,
            "y": 1,
            "z": 2,
            "elements": [
                "railcraft:coke_oven@0"
            ]
        },
        {
            "x": 1,
            "y": 1,
            "z": 1,
            "elements": [
                "railcraft:coke_oven@0"
            ]
        },
        {
            "x": 1,
            "y": 1,
            "z": 2,
            "elements": [
                "railcraft:coke_oven@0"
            ]
        },
        {
            "x": -1,
            "y": 2,
            "z": 0,
            "elements": [
                "railcraft:coke_oven@0"
            ]
        },
        {
            "x": -1,
            "y": 2,
            "z": 1,
            "elements": [
                "railcraft:coke_oven@0"
            ]
        },
        {
            "x": 0,
            "y": 2,
            "z": 0,
            "elements": [
                "railcraft:coke_oven@0"
            ]
        },
        {
            "x": -1,
            "y": 2,
            "z": 2,
            "elements": [
                "railcraft:coke_oven@0"
            ]
        },
        {
            "x": 0,
            "y": 2,
            "z": 1,
            "elements": [
                "railcraft:creosote@0"
            ]
        },
        {
            "x": 1,
            "y": 2,
            "z": 0,
            "elements": [
                "railcraft:coke_oven@0"
            ]
        }
    ]}